{
  "runnable": false,
  "phase": "seed",
  "error_type": "RuntimeError",
  "message": "Traceback (most recent call last):\n  File \"/home/wan00559/baseline/utils/compile_and_run.py\", line 222, in compare_and_bench\n    ref_out,  _ = _run_once(ref_model,  inp, dev)\n                  ^^^^^^^^^^^^^^^^^^^^^^^^^^^^^^^\n  File \"/home/wan00559/baseline/utils/compile_and_run.py\", line 115, in _run_once\n    model.to(dev).eval()\n    ^^^^^^^^^^^^^\n  File \"/home/wan00559/miniconda3/envs/maxk/lib/python3.11/site-packages/torch/nn/modules/module.py\", line 1355, in to\n    return self._apply(convert)\n           ^^^^^^^^^^^^^^^^^^^^\n  File \"/home/wan00559/miniconda3/envs/maxk/lib/python3.11/site-packages/torch/nn/modules/module.py\", line 915, in _apply\n    module._apply(fn)\n  File \"/home/wan00559/miniconda3/envs/maxk/lib/python3.11/site-packages/torch/nn/modules/module.py\", line 942, in _apply\n    param_applied = fn(param)\n                    ^^^^^^^^^\n  File \"/home/wan00559/miniconda3/envs/maxk/lib/python3.11/site-packages/torch/nn/modules/module.py\", line 1341, in convert\n    return t.to(\n           ^^^^^\nRuntimeError: CUDA error: an illegal memory access was encountered\nCUDA kernel errors might be asynchronously reported at some other API call, so the stacktrace below might be incorrect.\nFor debugging consider passing CUDA_LAUNCH_BLOCKING=1\nCompile with `TORCH_USE_CUDA_DSA` to enable device-side assertions.\n\n"
}